test_correct_login (login.login_test.loginTest) ... FAIL
test_passerr_login (login.login_test.loginTest) ... ok
test_usererr_login (login.login_test.loginTest) ... ERROR

======================================================================
ERROR: test_usererr_login (login.login_test.loginTest)
----------------------------------------------------------------------
Traceback (most recent call last):
  File "C:\Program Files (x86)\Python37-32\lib\site-packages\urllib3\connection.py", line 159, in _new_conn
    (self._dns_host, self.port), self.timeout, **extra_kw)
  File "C:\Program Files (x86)\Python37-32\lib\site-packages\urllib3\util\connection.py", line 80, in create_connection
    raise err
  File "C:\Program Files (x86)\Python37-32\lib\site-packages\urllib3\util\connection.py", line 70, in create_connection
    sock.connect(sa)
ConnectionRefusedError: [WinError 10061] 由于目标计算机积极拒绝，无法连接。

During handling of the above exception, another exception occurred:

Traceback (most recent call last):
  File "C:\Program Files (x86)\Python37-32\lib\site-packages\urllib3\connectionpool.py", line 600, in urlopen
    chunked=chunked)
  File "C:\Program Files (x86)\Python37-32\lib\site-packages\urllib3\connectionpool.py", line 354, in _make_request
    conn.request(method, url, **httplib_request_kw)
  File "C:\Program Files (x86)\Python37-32\lib\http\client.py", line 1229, in request
    self._send_request(method, url, body, headers, encode_chunked)
  File "C:\Program Files (x86)\Python37-32\lib\http\client.py", line 1275, in _send_request
    self.endheaders(body, encode_chunked=encode_chunked)
  File "C:\Program Files (x86)\Python37-32\lib\http\client.py", line 1224, in endheaders
    self._send_output(message_body, encode_chunked=encode_chunked)
  File "C:\Program Files (x86)\Python37-32\lib\http\client.py", line 1016, in _send_output
    self.send(msg)
  File "C:\Program Files (x86)\Python37-32\lib\http\client.py", line 956, in send
    self.connect()
  File "C:\Program Files (x86)\Python37-32\lib\site-packages\urllib3\connection.py", line 181, in connect
    conn = self._new_conn()
  File "C:\Program Files (x86)\Python37-32\lib\site-packages\urllib3\connection.py", line 168, in _new_conn
    self, "Failed to establish a new connection: %s" % e)
urllib3.exceptions.NewConnectionError: <urllib3.connection.HTTPConnection object at 0x031E0DD0>: Failed to establish a new connection: [WinError 10061] 由于目标计算机积极拒绝，无法连接。

During handling of the above exception, another exception occurred:

Traceback (most recent call last):
  File "D:\私人\takin\model\modules\yancloud\login\login_test.py", line 30, in test_usererr_login
    ts=lg.xinxi()
  File "D:\私人\takin\model\modules\yancloud\login\login_procs.py", line 54, in xinxi
    a=brc.text()
  File "D:\私人\takin\model\modules\mains\browser.py", line 216, in text
    info=em.get_attribute("textContent")
  File "C:\Program Files (x86)\Python37-32\lib\site-packages\selenium\webdriver\remote\webelement.py", line 141, in get_attribute
    self, name)
  File "C:\Program Files (x86)\Python37-32\lib\site-packages\selenium\webdriver\remote\webdriver.py", line 636, in execute_script
    'args': converted_args})['value']
  File "C:\Program Files (x86)\Python37-32\lib\site-packages\selenium\webdriver\remote\webdriver.py", line 319, in execute
    response = self.command_executor.execute(driver_command, params)
  File "C:\Program Files (x86)\Python37-32\lib\site-packages\selenium\webdriver\remote\remote_connection.py", line 374, in execute
    return self._request(command_info[0], url, body=data)
  File "C:\Program Files (x86)\Python37-32\lib\site-packages\selenium\webdriver\remote\remote_connection.py", line 397, in _request
    resp = self._conn.request(method, url, body=body, headers=headers)
  File "C:\Program Files (x86)\Python37-32\lib\site-packages\urllib3\request.py", line 72, in request
    **urlopen_kw)
  File "C:\Program Files (x86)\Python37-32\lib\site-packages\urllib3\request.py", line 150, in request_encode_body
    return self.urlopen(method, url, **extra_kw)
  File "C:\Program Files (x86)\Python37-32\lib\site-packages\urllib3\poolmanager.py", line 323, in urlopen
    response = conn.urlopen(method, u.request_uri, **kw)
  File "C:\Program Files (x86)\Python37-32\lib\site-packages\urllib3\connectionpool.py", line 667, in urlopen
    **response_kw)
  File "C:\Program Files (x86)\Python37-32\lib\site-packages\urllib3\connectionpool.py", line 667, in urlopen
    **response_kw)
  File "C:\Program Files (x86)\Python37-32\lib\site-packages\urllib3\connectionpool.py", line 667, in urlopen
    **response_kw)
  File "C:\Program Files (x86)\Python37-32\lib\site-packages\urllib3\connectionpool.py", line 638, in urlopen
    _stacktrace=sys.exc_info()[2])
  File "C:\Program Files (x86)\Python37-32\lib\site-packages\urllib3\util\retry.py", line 398, in increment
    raise MaxRetryError(_pool, url, error or ResponseError(cause))
urllib3.exceptions.MaxRetryError: HTTPConnectionPool(host='127.0.0.1', port=51058): Max retries exceeded with url: /session/f62a79a6efceb828bc7d2f13d1344cb9/execute/sync (Caused by NewConnectionError('<urllib3.connection.HTTPConnection object at 0x031E0DD0>: Failed to establish a new connection: [WinError 10061] 由于目标计算机积极拒绝，无法连接。'))

======================================================================
FAIL: test_correct_login (login.login_test.loginTest)
----------------------------------------------------------------------
Traceback (most recent call last):
  File "D:\私人\takin\model\modules\yancloud\login\login_test.py", line 24, in test_correct_login
    self.assertEqual(ts, text)
AssertionError: '登录成功' != '登录1成功'
- 登录成功
+ 登录1成功
?   +


----------------------------------------------------------------------
Ran 3 tests in 27.018s

FAILED (failures=1, errors=1)
